<?xml version='1.0' encoding='utf-8'?>
<robot name="URDF_to_USD">
    <link name="teko_body">
        <inertial>
            <origin xyz="-0.03322487786188057 -3.210624819559104e-07 -0.01222742277589171" rpy="0.0 0.0 0.0" />
            <mass value="55.30155380400797" />
            <inertia ixx="0.2786499612735865" iyy="0.6148616643483823" izz="0.5051691379248819" ixy="8.485416470758536e-07" iyz="-2.6893582656831792e-06" ixz="0.01263665637919702" />
        </inertial>
        <visual name="teko_body_visual">
            <origin xyz="0.0 0.0 0.0" rpy="0.0 0.0 0.0" />
            <geometry>
                <mesh filename="meshes/teko_body.stl" scale="0.001 0.001 0.001" />
            </geometry>
        </visual>
        <collision name="teko_body_collision">
            <origin xyz="0.0 0.0 0.0" rpy="0.0 0.0 0.0" />
            <geometry>
                <mesh filename="meshes/teko_body.stl" scale="0.001 0.001 0.001" />
            </geometry>
        </collision>
    </link>
    <link name="teko_lidar">
        <inertial>
            <origin xyz="-1.7763568394002505e-17 -1.0157093023226922e-16 0.013450000000000016" rpy="0.0 -0.0 0.0" />
            <mass value="0.5930812388937148" />
            <inertia ixx="0.00016831843253549243" iyy="0.0001683184325355011" izz="0.0002651102791916809" ixy="-1.417197381670121e-18" iyz="3.2429099405817336e-19" ixz="-4.336808689942018e-19" />
        </inertial>
        <visual name="teko_lidar_visual">
            <origin xyz="-0.1376 0.0 0.0455" rpy="3.141592653589793 -0.0 0.0" />
            <geometry>
                <mesh filename="meshes/teko_lidar.stl" scale="0.001 0.001 0.001" />
            </geometry>
        </visual>
        <collision name="teko_lidar_collision">
            <origin xyz="-0.1376 0.0 0.0455" rpy="3.141592653589793 -0.0 0.0" />
            <geometry>
                <mesh filename="meshes/teko_lidar.stl" scale="0.001 0.001 0.001" />
            </geometry>
        </collision>
    </link>
    <link name="teko_camera">
        <inertial>
            <origin xyz="-1.479114197289397e-33 -0.035 0.0015000000000000213" rpy="0.0 -0.0 0.0" />
            <mass value="0.014130001214191378" />
            <inertia ixx="6.888377646920279e-07" iyy="7.465349676462276e-07" izz="1.414177730516831e-06" ixy="3.5214296447818196e-22" iyz="-2.710505431213761e-20" ixz="-9.151013280472862e-22" />
        </inertial>
        <visual name="teko_camera_visual">
            <origin xyz="-2.6023744481881267e-18 -0.0775 -0.17250000000000001" rpy="-1.5707963267948966 1.5707963267948966 0" />
            <geometry>
                <mesh filename="meshes/teko_camera.stl" scale="0.001 0.001 0.001" />
            </geometry>
        </visual>
        <collision name="teko_camera_collision">
            <origin xyz="-2.6023744481881267e-18 -0.0775 -0.17250000000000001" rpy="-1.5707963267948966 1.5707963267948966 0" />
            <geometry>
                <mesh filename="meshes/teko_camera.stl" scale="0.001 0.001 0.001" />
            </geometry>
        </collision>
    </link>
    <link name="teko_connect_male">
        <inertial>
            <origin xyz="1.2851451110364246e-05 0.012508471421193237 0.028637477444663766" rpy="0.0 -0.0 0.0" />
            <mass value="0.6070410060978664" />
            <inertia ixx="0.00021799578145698453" iyy="0.0003112272271409422" izz="0.00018351696205621887" ixy="1.2573674757801726e-07" iyz="-2.1845249203090826e-05" ixz="-2.9472485848962832e-08" />
        </inertial>
        <visual name="teko_connect_male_visual">
            <origin xyz="0.0004507494942305308 -0.05551125236737327 -0.17250000000000001" rpy="1.5707963267948968 -1.5707963267948966 0" />
            <geometry>
                <mesh filename="meshes/teko_connect_male.stl" scale="0.001 0.001 0.001" />
            </geometry>
        </visual>
        <collision name="teko_connect_male_collision">
            <origin xyz="0.0004507494942305308 -0.05551125236737327 -0.17250000000000001" rpy="1.5707963267948968 -1.5707963267948966 0" />
            <geometry>
                <mesh filename="meshes/teko_connect_male.stl" scale="0.001 0.001 0.001" />
            </geometry>
        </collision>
    </link>
    <link name="teko_pin">
        <inertial>
            <origin xyz="-0.0021138833462986018 4.895877659592601e-06 0.028069331254574975" rpy="0.0 -0.0 0.0" />
            <mass value="0.04124822257656457" />
            <inertia ixx="4.970374219001247e-06" iyy="4.978093813264549e-06" izz="1.401522672915713e-06" ixy="1.8001458984546494e-11" iyz="-1.0585795096708065e-09" ixz="4.563625663486044e-07" />
        </inertial>
        <visual name="teko_pin_visual">
            <origin xyz="0.054917629052547226 0.00022318111558906358 -0.22340000000000002" rpy="-3.141592653589793 -1.5707963267948966 0" />
            <geometry>
                <mesh filename="meshes/teko_pin.stl" scale="0.001 0.001 0.001" />
            </geometry>
        </visual>
        <collision name="teko_pin_collision">
            <origin xyz="0.054917629052547226 0.00022318111558906358 -0.22340000000000002" rpy="-3.141592653589793 -1.5707963267948966 0" />
            <geometry>
                <mesh filename="meshes/teko_pin.stl" scale="0.001 0.001 0.001" />
            </geometry>
        </collision>
    </link>
    <link name="teko_connect_female">
        <inertial>
            <origin xyz="-0.05272051512398969 -0.00014116164225701528 0.029277598163811727" rpy="0.0 -0.0 0.0" />
            <mass value="0.7378276822773233" />
            <inertia ixx="0.0004584022715899243" iyy="0.00035624680955673865" izz="0.0002877800509507389" ixy="1.1841968589660358e-07" iyz="3.5006063005911777e-07" ixz="-9.997220132536636e-06" />
        </inertial>
        <visual name="teko_connect_female_visual">
            <origin xyz="0.01579675177311726 0.0014317706669016526 -0.17256471994939027" rpy="-1.570796326794907 1.5633679107606986 -1.5707963267948968" />
            <geometry>
                <mesh filename="meshes/teko_connect_female.stl" scale="0.001 0.001 0.001" />
            </geometry>
        </visual>
        <collision name="teko_connect_female_collision">
            <origin xyz="0.01579675177311726 0.0014317706669016526 -0.17256471994939027" rpy="-1.570796326794907 1.5633679107606986 -1.5707963267948968" />
            <geometry>
                <mesh filename="meshes/teko_connect_female.stl" scale="0.001 0.001 0.001" />
            </geometry>
        </collision>
    </link>
    <link name="teko_FL">
        <inertial>
            <origin xyz="-3.552713678800501e-17 3.552713678800501e-17 0.020200000000000138" rpy="0.0 -0.0 0.0" />
            <mass value="0.5429860236533911" />
            <inertia ixx="0.000147833694935387" iyy="0.00014783369493538527" izz="0.0001479607118097491" ixy="0.0" iyz="-1.734723475976807e-18" ixz="-1.734723475976807e-18" />
        </inertial>
        <visual name="teko_FL_visual">
            <origin xyz="-0.10093 -0.1625 -0.0723" rpy="1.5707963267948966 -0.0 0.0" />
            <geometry>
                <mesh filename="meshes/teko_FL.stl" scale="0.001 0.001 0.001" />
            </geometry>
        </visual>
        <collision name="teko_FL_collision">
            <origin xyz="-0.10093 -0.1625 -0.0723" rpy="1.5707963267948966 -0.0 0.0" />
            <geometry>
                <mesh filename="meshes/teko_FL.stl" scale="0.001 0.001 0.001" />
            </geometry>
        </collision>
    </link>
    <link name="teko_BL">
        <inertial>
            <origin xyz="-5.329070518200751e-17 3.552713678800501e-17 0.020200000000000155" rpy="0.0 -0.0 0.0" />
            <mass value="0.5429860236533901" />
            <inertia ixx="0.0001478336949353766" iyy="0.0001478336949353818" izz="0.00014796071180974216" ixy="-1.734723475976807e-18" iyz="0.0" ixz="-1.3010426069826053e-18" />
        </inertial>
        <visual name="teko_BL_visual">
            <origin xyz="0.07007 -0.1625 -0.0723" rpy="1.5707963267948966 -0.0 0.0" />
            <geometry>
                <mesh filename="meshes/teko_BL.stl" scale="0.001 0.001 0.001" />
            </geometry>
        </visual>
        <collision name="teko_BL_collision">
            <origin xyz="0.07007 -0.1625 -0.0723" rpy="1.5707963267948966 -0.0 0.0" />
            <geometry>
                <mesh filename="meshes/teko_BL.stl" scale="0.001 0.001 0.001" />
            </geometry>
        </collision>
    </link>
    <link name="teko_FR">
        <inertial>
            <origin xyz="-1.7763568394002505e-17 -7.105427357601002e-17 0.0201" rpy="0.0 -0.0 0.0" />
            <mass value="0.5402979740313447" />
            <inertia ixx="0.00014637604468200477" iyy="0.0001463760446820065" izz="0.00014722823303840726" ixy="-1.734723475976807e-18" iyz="0.0" ixz="1.734723475976807e-18" />
        </inertial>
        <visual name="teko_FR_visual">
            <origin xyz="-0.10093 0.1625 -0.0725" rpy="-1.5707963267948966 -0.0 0.0" />
            <geometry>
                <mesh filename="meshes/teko_FR.stl" scale="0.001 0.001 0.001" />
            </geometry>
        </visual>
        <collision name="teko_FR_collision">
            <origin xyz="-0.10093 0.1625 -0.0725" rpy="-1.5707963267948966 -0.0 0.0" />
            <geometry>
                <mesh filename="meshes/teko_FR.stl" scale="0.001 0.001 0.001" />
            </geometry>
        </collision>
    </link>
    <link name="teko_BR">
        <inertial>
            <origin xyz="-5.329070518200751e-17 -7.105427357601002e-17 0.0201" rpy="0.0 -0.0 0.0" />
            <mass value="0.5402979740313437" />
            <inertia ixx="0.00014637604468200824" iyy="0.00014637604468200477" izz="0.00014722823303840726" ixy="8.673617379884035e-19" iyz="0.0" ixz="0.0" />
        </inertial>
        <visual name="teko_BR_visual">
            <origin xyz="0.07007 0.1625 -0.0725" rpy="-1.5707963267948966 -0.0 0.0" />
            <geometry>
                <mesh filename="meshes/teko_BR.stl" scale="0.001 0.001 0.001" />
            </geometry>
        </visual>
        <collision name="teko_BR_collision">
            <origin xyz="0.07007 0.1625 -0.0725" rpy="-1.5707963267948966 -0.0 0.0" />
            <geometry>
                <mesh filename="meshes/teko_BR.stl" scale="0.001 0.001 0.001" />
            </geometry>
        </collision>
    </link>
    <joint name="teko_connect_male_Deslizador-19" type="prismatic">
        <origin xyz="7.336e-05 0.009346610000000002 0.0509" rpy="0.0 -0.0 -1.5707963267948966" />
        <parent link="teko_connect_male" />
        <child link="teko_pin" />
        <axis xyz="0.0 0.0 1.0" />
        <limit lower="-0.015" upper="0.0" effort="1000000" velocity="1000000" />
    </joint>
    <joint name="teko_body_Rígido-29" type="fixed">
        <origin xyz="0.17250000000000001 0.0 -0.0475" rpy="-1.5707963267948966 -0.0 -1.5707963267948966" />
        <parent link="teko_body" />
        <child link="teko_connect_male" />
    </joint>
    <joint name="teko_body_Rígido-30" type="fixed">
        <origin xyz="-0.17250000000000001 0.0 -0.01" rpy="-0.0 -1.5707963267948966 0" />
        <parent link="teko_body" />
        <child link="teko_connect_female" />
    </joint>
    <joint name="teko_body_Revolucionar-31" type="continuous">
        <origin xyz="0.10093 -0.0725 -0.1625" rpy="1.5707963267948966 -0.0 0.0" />
        <parent link="teko_body" />
        <child link="teko_FR" />
        <axis xyz="0.0 0.0 1.0" />
    </joint>
    <joint name="teko_body_Revolucionar-32" type="continuous">
        <origin xyz="0.10093 0.0723 -0.1625" rpy="-1.5707963267948966 -0.0 0.0" />
        <parent link="teko_body" />
        <child link="teko_FL" />
        <axis xyz="0.0 0.0 1.0" />
    </joint>
    <joint name="teko_body_Revolucionar-33" type="continuous">
        <origin xyz="-0.07007 -0.0725 -0.1625" rpy="1.5707963267948966 -0.0 0.0" />
        <parent link="teko_body" />
        <child link="teko_BR" />
        <axis xyz="0.0 0.0 1.0" />
    </joint>
    <joint name="teko_body_Revolucionar-34" type="continuous">
        <origin xyz="-0.07007 0.0723 -0.1625" rpy="-1.5707963267948966 -0.0 0.0" />
        <parent link="teko_body" />
        <child link="teko_BL" />
        <axis xyz="0.0 0.0 1.0" />
    </joint>
    <joint name="teko_body_Revolucionar-35" type="continuous">
        <origin xyz="0.1376 0.0 0.0455" rpy="3.141592653589793 -0.0 0.0" />
        <parent link="teko_body" />
        <child link="teko_lidar" />
        <axis xyz="0.0 0.0 1.0" />
    </joint>
    <joint name="teko_body_Rígido-36" type="fixed">
        <origin xyz="-0.17250000000000001 0.0 0.08750000000000001" rpy="1.5707963267948966 -0.0 -1.5707963267948966" />
        <parent link="teko_body" />
        <child link="teko_camera" />
    </joint>
</robot>