<?xml version='1.0' encoding='utf-8'?>
<robot name="teko_urdf">
    <link name="TEKO_Camera">
        <inertial>
            <origin xyz="-0.000601992828460793 -0.029951130024606764 0.0013139717851243305" rpy="0.0 -0.0 0.0" />
            <mass value="0.0012386847723750993" />
            <inertia ixx="4.838735248432677e-08" iyy="4.6264823358249055e-08" izz="8.802945438877071e-08" ixy="2.6707303999946516e-10" iyz="1.2190327128913994e-10" ixz="2.256468991696752e-09" />
        </inertial>
        <visual name="TEKO_Camera_visual">
            <origin xyz="3.584941588377633e-17 -0.060999995393176895 -0.17200000000000018" rpy="-1.5707963267948966 1.5707963267948966 0" />
            <geometry>
                <mesh filename="meshes/TEKO_Camera.stl" scale="0.001 0.001 0.001" />
            </geometry>
        </visual>
        <collision name="TEKO_Camera_collision">
            <origin xyz="3.584941588377633e-17 -0.060999995393176895 -0.17200000000000018" rpy="-1.5707963267948966 1.5707963267948966 0" />
            <geometry>
                <mesh filename="meshes/TEKO_Camera.stl" scale="0.001 0.001 0.001" />
            </geometry>
        </collision>
    </link>
    <link name="TEKO_ChassiUpper">
        <inertial>
            <origin xyz="-0.01691362208633511 -9.603738555750968e-06 -4.994864342328875e-06" rpy="0.0 0.0 0.0" />
            <mass value="2.9526504354808645" />
            <inertia ixx="0.0199960439538497" iyy="0.047815403666796465" izz="0.04502372003246011" ixy="1.0964745924838652e-06" iyz="-7.291871623940826e-07" ixz="0.0009130525901427835" />
        </inertial>
        <visual name="TEKO_ChassiUpper_visual">
            <origin xyz="0.0 0.0 0.0" rpy="0.0 0.0 0.0" />
            <geometry>
                <mesh filename="meshes/TEKO_ChassiUpper.stl" scale="0.001 0.001 0.001" />
            </geometry>
        </visual>
        <collision name="TEKO_ChassiUpper_collision">
            <origin xyz="0.0 0.0 0.0" rpy="0.0 0.0 0.0" />
            <geometry>
                <mesh filename="meshes/TEKO_ChassiUpper.stl" scale="0.001 0.001 0.001" />
            </geometry>
        </collision>
    </link>
    <link name="TEKO_MotorRight-1">
        <inertial>
            <origin xyz="6.074188593707675e-06 0.012145878223398139 0.02035004173492432" rpy="0.0 -0.0 0.0" />
            <mass value="0.3338580457563576" />
            <inertia ixx="8.97336621287154e-05" iyy="5.310595517076444e-05" izz="8.072317212791912e-05" ixy="2.4637803349575327e-08" iyz="-2.442400799483515e-06" ixz="3.032995306295749e-08" />
        </inertial>
        <visual name="TEKO_MotorRight-1_visual">
            <origin xyz="0.09334722333997801 0.15314999999999787 0.07179999989294208" rpy="-1.5707963267948657 -0.0 0.0" />
            <geometry>
                <mesh filename="meshes/TEKO_MotorRight-1.stl" scale="0.001 0.001 0.001" />
            </geometry>
        </visual>
        <collision name="TEKO_MotorRight-1_collision">
            <origin xyz="0.09334722333997801 0.15314999999999787 0.07179999989294208" rpy="-1.5707963267948657 -0.0 0.0" />
            <geometry>
                <mesh filename="meshes/TEKO_MotorRight-1.stl" scale="0.001 0.001 0.001" />
            </geometry>
        </collision>
    </link>
    <link name="TEKO_Body">
        <inertial>
            <origin xyz="-0.032229605357285904 -0.059787270107073937 0.04669874598501995" rpy="0.0 -0.0 0.0" />
            <mass value="0.8515121958050561" />
            <inertia ixx="0.004579249363672409" iyy="0.005852943616159434" izz="0.008936946269037953" ixy="-2.2171299152618125e-15" iyz="1.9095510762900947e-17" ixz="-0.0003381937410805074" />
        </inertial>
        <visual name="TEKO_Body_visual">
            <origin xyz="-0.006287706660021951 -0.059587270107062995 -0.05750000000000014" rpy="3.141592653589793 -0.0 0.0" />
            <geometry>
                <mesh filename="meshes/TEKO_Body.stl" scale="0.001 0.001 0.001" />
            </geometry>
        </visual>
        <collision name="TEKO_Body_collision">
            <origin xyz="-0.006287706660021951 -0.059587270107062995 -0.05750000000000014" rpy="3.141592653589793 -0.0 0.0" />
            <geometry>
                <mesh filename="meshes/TEKO_Body.stl" scale="0.001 0.001 0.001" />
            </geometry>
        </collision>
    </link>
    <link name="TEKO_WheelBackLeft">
        <inertial>
            <origin xyz="-6.392622385664737e-06 3.516300231289904e-06 0.016665183221117347" rpy="0.0 -0.0 0.0" />
            <mass value="0.26591647257735795" />
            <inertia ixx="9.323502247751518e-05" iyy="9.320985642880236e-05" izz="0.00010878868702308975" ixy="-1.5932751675721418e-08" iyz="-2.2561326157993777e-09" ixz="3.0307445485558415e-10" />
        </inertial>
        <visual name="TEKO_WheelBackLeft_visual">
            <origin xyz="0.09334722333997805 -0.15315000000000015 -0.08219999989293701" rpy="1.5707963267948966 -0.0 0.0" />
            <geometry>
                <mesh filename="meshes/TEKO_WheelBackLeft.stl" scale="0.001 0.001 0.001" />
            </geometry>
        </visual>
        <collision name="TEKO_WheelBackLeft_collision">
            <origin xyz="0.09334722333997805 -0.15315000000000015 -0.08219999989293701" rpy="1.5707963267948966 -0.0 0.0" />
            <geometry>
                <mesh filename="meshes/TEKO_WheelBackLeft.stl" scale="0.001 0.001 0.001" />
            </geometry>
        </collision>
    </link>
    <link name="TEKO_WheelFrontLeft">
        <inertial>
            <origin xyz="-6.392623328341785e-06 3.516300230952396e-06 0.016665183221117347" rpy="0.0 -0.0 0.0" />
            <mass value="0.26591647257735956" />
            <inertia ixx="9.323502247750998e-05" iyy="9.320985642570414e-05" izz="0.00010878868701999153" ixy="-1.593278872204229e-08" iyz="-2.2561326123299308e-09" ixz="3.0305054125878694e-10" />
        </inertial>
        <visual name="TEKO_WheelFrontLeft_visual">
            <origin xyz="-0.08055277666002196 -0.15315000000000015 -0.08219999989293701" rpy="1.5707963267948966 -0.0 0.0" />
            <geometry>
                <mesh filename="meshes/TEKO_WheelFrontLeft.stl" scale="0.001 0.001 0.001" />
            </geometry>
        </visual>
        <collision name="TEKO_WheelFrontLeft_collision">
            <origin xyz="-0.08055277666002196 -0.15315000000000015 -0.08219999989293701" rpy="1.5707963267948966 -0.0 0.0" />
            <geometry>
                <mesh filename="meshes/TEKO_WheelFrontLeft.stl" scale="0.001 0.001 0.001" />
            </geometry>
        </collision>
    </link>
    <link name="TEKO_ConnectorRear">
        <inertial>
            <origin xyz="-2.671080714359701e-05 -0.014444350573903338 0.03165240374063423" rpy="0.0 9.683598452104271e-48 0.0" />
            <mass value="0.610171436349428" />
            <inertia ixx="0.0003131463573876822" iyy="0.0004380018496381241" izz="0.00028384080125114057" ixy="1.355720866895629e-07" iyz="-9.906871849972923e-06" ixz="-1.5751535527045858e-07" />
        </inertial>
        <visual name="TEKO_ConnectorRear_visual">
            <origin xyz="-5.399826870294263e-18 0.057999999999999996 -0.17250000000000001" rpy="-1.5707963267948968 1.5707963267948966 0" />
            <geometry>
                <mesh filename="meshes/TEKO_ConnectorRear.stl" scale="0.001 0.001 0.001" />
            </geometry>
        </visual>
        <collision name="TEKO_ConnectorRear_collision">
            <origin xyz="-5.399826870294263e-18 0.057999999999999996 -0.17250000000000001" rpy="-1.5707963267948968 1.5707963267948966 0" />
            <geometry>
                <mesh filename="meshes/TEKO_ConnectorRear.stl" scale="0.001 0.001 0.001" />
            </geometry>
        </collision>
    </link>
    <link name="TEKO_Roof">
        <inertial>
            <origin xyz="-0.18724256503072337 -0.06693503856058061 0.020350910244172536" rpy="0.0 -0.0 0.0" />
            <mass value="3.3827878946759804" />
            <inertia ixx="0.007869878080337067" iyy="0.031861060306351434" izz="0.03860295468346278" ixy="-1.3108241382741754e-05" iyz="-3.1162768180491877e-06" ixz="-0.001593265540209336" />
        </inertial>
        <visual name="TEKO_Roof_visual">
            <origin xyz="-0.17249999999999996 -0.06680019035121892 -0.07730000000000005" rpy="0.0 -0.0 0.0" />
            <geometry>
                <mesh filename="meshes/TEKO_Roof.stl" scale="0.001 0.001 0.001" />
            </geometry>
        </visual>
        <collision name="TEKO_Roof_collision">
            <origin xyz="-0.17249999999999996 -0.06680019035121892 -0.07730000000000005" rpy="0.0 -0.0 0.0" />
            <geometry>
                <mesh filename="meshes/TEKO_Roof.stl" scale="0.001 0.001 0.001" />
            </geometry>
        </collision>
    </link>
    <link name="TEKO_ConnectorFront">
        <inertial>
            <origin xyz="-1.3458835430142643e-05 0.0028438747289007437 0.03353015198616344" rpy="0.0 -0.0 0.0" />
            <mass value="0.5832810178770284" />
            <inertia ixx="0.0003566231567307815" iyy="0.00045060586354731674" izz="0.0001811351174753886" ixy="3.5674963365720085e-08" iyz="-1.7882469364578768e-05" ixz="1.671010467764308e-07" />
        </inertial>
        <visual name="TEKO_ConnectorFront_visual">
            <origin xyz="-0.0001392114616602822 -0.03509235969598555 -0.16799999924004078" rpy="1.5707963267948968 -1.5707963267948966 0" />
            <geometry>
                <mesh filename="meshes/TEKO_ConnectorFront.stl" scale="0.001 0.001 0.001" />
            </geometry>
        </visual>
        <collision name="TEKO_ConnectorFront_collision">
            <origin xyz="-0.0001392114616602822 -0.03509235969598555 -0.16799999924004078" rpy="1.5707963267948968 -1.5707963267948966 0" />
            <geometry>
                <mesh filename="meshes/TEKO_ConnectorFront.stl" scale="0.001 0.001 0.001" />
            </geometry>
        </collision>
    </link>
    <link name="TEKO_WallBack">
        <inertial>
            <origin xyz="-0.0005000000000000782 -5.407566755488702e-17 0.057497642303410555" rpy="0.0 -0.0 0.0" />
            <mass value="0.4287599869279915" />
            <inertia ixx="0.000794910589929738" iyy="0.00047338373573235434" izz="0.00032331335414291507" ixy="-4.90872642670089e-19" iyz="-4.192039119802366e-19" ixz="9.482004448919858e-19" />
        </inertial>
        <visual name="TEKO_WallBack_visual">
            <origin xyz="0.16949999999999998 -1.3512443515129036e-06 0.05749647508845193" rpy="0.0 -0.0 0.0" />
            <geometry>
                <mesh filename="meshes/TEKO_WallBack.stl" scale="0.001 0.001 0.001" />
            </geometry>
        </visual>
        <collision name="TEKO_WallBack_collision">
            <origin xyz="0.16949999999999998 -1.3512443515129036e-06 0.05749647508845193" rpy="0.0 -0.0 0.0" />
            <geometry>
                <mesh filename="meshes/TEKO_WallBack.stl" scale="0.001 0.001 0.001" />
            </geometry>
        </collision>
    </link>
    <link name="TEKO_GlassAruco">
        <inertial>
            <origin xyz="-0.055749999850988385 -0.04749999999999461 0.002499966325032412" rpy="0.0 -0.0 0.0" />
            <mass value="0.4157500974060791" />
            <inertia ixx="0.00031354484209590247" iyy="0.00043159188537814" izz="0.0007434044814638818" ixy="3.3881317890172014e-21" iyz="2.371692252312041e-20" ixz="2.168404344971009e-19" />
        </inertial>
        <visual name="TEKO_GlassAruco_visual">
            <origin xyz="-0.15049999985098847 -0.04753462034064349 0.05050001000000001" rpy="0.0 -0.0 0.0" />
            <geometry>
                <mesh filename="meshes/TEKO_GlassAruco.stl" scale="0.001 0.001 0.001" />
            </geometry>
        </visual>
        <collision name="TEKO_GlassAruco_collision">
            <origin xyz="-0.15049999985098847 -0.04753462034064349 0.05050001000000001" rpy="0.0 -0.0 0.0" />
            <geometry>
                <mesh filename="meshes/TEKO_GlassAruco.stl" scale="0.001 0.001 0.001" />
            </geometry>
        </collision>
    </link>
    <link name="TEKO_WheelBackRight">
        <inertial>
            <origin xyz="-6.865791335322058e-06 -3.243595376947184e-06 0.01666526399962489" rpy="0.0 -0.0 0.0" />
            <mass value="0.26593113960593123" />
            <inertia ixx="9.324121331082645e-05" iyy="9.321577936850529e-05" izz="0.0001087979109481059" ixy="1.5887236907118074e-08" iyz="1.9369397179919146e-09" ixz="7.542198948717882e-10" />
        </inertial>
        <visual name="TEKO_WheelBackRight_visual">
            <origin xyz="0.09334722333997805 0.15315000000000012 -0.08220000010706269" rpy="-1.5707963267948966 -0.0 0.0" />
            <geometry>
                <mesh filename="meshes/TEKO_WheelBackRight.stl" scale="0.001 0.001 0.001" />
            </geometry>
        </visual>
        <collision name="TEKO_WheelBackRight_collision">
            <origin xyz="0.09334722333997805 0.15315000000000012 -0.08220000010706269" rpy="-1.5707963267948966 -0.0 0.0" />
            <geometry>
                <mesh filename="meshes/TEKO_WheelBackRight.stl" scale="0.001 0.001 0.001" />
            </geometry>
        </collision>
    </link>
    <link name="TEKO_WheelFrontRight">
        <inertial>
            <origin xyz="-6.8657922777504155e-06 -3.2435953767517844e-06 0.01666526399962514" rpy="0.0 -0.0 0.0" />
            <mass value="0.265931139605929" />
            <inertia ixx="9.324121331082472e-05" iyy="9.321577936540273e-05" izz="0.00010879791094500768" ixy="1.5887273952137904e-08" iyz="1.9369397153898293e-09" ixz="7.541959817086719e-10" />
        </inertial>
        <visual name="TEKO_WheelFrontRight_visual">
            <origin xyz="-0.08055277666002192 0.15315000000000012 -0.08220000010706269" rpy="-1.5707963267948966 -0.0 0.0" />
            <geometry>
                <mesh filename="meshes/TEKO_WheelFrontRight.stl" scale="0.001 0.001 0.001" />
            </geometry>
        </visual>
        <collision name="TEKO_WheelFrontRight_collision">
            <origin xyz="-0.08055277666002192 0.15315000000000012 -0.08220000010706269" rpy="-1.5707963267948966 -0.0 0.0" />
            <geometry>
                <mesh filename="meshes/TEKO_WheelFrontRight.stl" scale="0.001 0.001 0.001" />
            </geometry>
        </collision>
    </link>
    <link name="TEKO_GlassBase">
        <inertial>
            <origin xyz="0.17250000000000001 -0.0675 -0.002250000000000032" rpy="0.0 -0.0 0.0" />
            <mass value="1.645261875" />
            <inertia ixx="0.00250151785207031" iyy="0.01632171760207031" izz="0.0188176826953125" ixy="-8.462431693707278e-19" iyz="2.0328790734103208e-19" ixz="1.517150849394966e-18" />
        </inertial>
        <visual name="TEKO_GlassBase_visual">
            <origin xyz="0.17250000000000001 -0.06749999999999999 0.07730000000000001" rpy="0.0 -0.0 6.123233995736766e-17" />
            <geometry>
                <mesh filename="meshes/TEKO_GlassBase.stl" scale="0.001 0.001 0.001" />
            </geometry>
        </visual>
        <collision name="TEKO_GlassBase_collision">
            <origin xyz="0.17250000000000001 -0.06749999999999999 0.07730000000000001" rpy="0.0 -0.0 6.123233995736766e-17" />
            <geometry>
                <mesh filename="meshes/TEKO_GlassBase.stl" scale="0.001 0.001 0.001" />
            </geometry>
        </collision>
    </link>
    <link name="TEKO_MotorRight">
        <inertial>
            <origin xyz="6.0751766787703335e-06 -0.012145879017749639 0.020350041878201424" rpy="0.0 -0.0 0.0" />
            <mass value="0.3338580304078961" />
            <inertia ixx="8.973365588505183e-05" iyy="5.310595248353856e-05" izz="8.072316618446852e-05" ixy="-2.4641531955540974e-08" iyz="2.4424011774255502e-06" ixz="3.032954938543206e-08" />
        </inertial>
        <visual name="TEKO_MotorRight_visual">
            <origin xyz="0.09334722333997808 -0.15314999999999787 0.07170000010706776" rpy="1.5707963267948657 -0.0 0.0" />
            <geometry>
                <mesh filename="meshes/TEKO_MotorRight.stl" scale="0.001 0.001 0.001" />
            </geometry>
        </visual>
        <collision name="TEKO_MotorRight_collision">
            <origin xyz="0.09334722333997808 -0.15314999999999787 0.07170000010706776" rpy="1.5707963267948657 -0.0 0.0" />
            <geometry>
                <mesh filename="meshes/TEKO_MotorRight.stl" scale="0.001 0.001 0.001" />
            </geometry>
        </collision>
    </link>
    <link name="TEKO_BoardSupport">
        <inertial>
            <origin xyz="-0.06629024009766754 -0.031818425668824056 0.06766276732786157" rpy="0.0 9.973250828902048e-43 0.0" />
            <mass value="0.5529059120022721" />
            <inertia ixx="0.0017570483083201663" iyy="0.0015057952033683208" izz="0.0008177542824251939" ixy="3.112369912145077e-06" iyz="6.2997142061253e-05" ixz="-1.7070123732179736e-06" />
        </inertial>
        <visual name="TEKO_BoardSupport_visual">
            <origin xyz="-0.06675 -0.05770000000000001 0.03270000000000037" rpy="1.5707963267948966 1.5707963267948966 0" />
            <geometry>
                <mesh filename="meshes/TEKO_BoardSupport.stl" scale="0.001 0.001 0.001" />
            </geometry>
        </visual>
        <collision name="TEKO_BoardSupport_collision">
            <origin xyz="-0.06675 -0.05770000000000001 0.03270000000000037" rpy="1.5707963267948966 1.5707963267948966 0" />
            <geometry>
                <mesh filename="meshes/TEKO_BoardSupport.stl" scale="0.001 0.001 0.001" />
            </geometry>
        </collision>
    </link>
    <link name="TEKO_BoardSupport-1">
        <inertial>
            <origin xyz="-0.10908583622641083 -0.06696231798810534 0.04843812945531937" rpy="0.0 -0.0 0.0" />
            <mass value="2.3849467441322254" />
            <inertia ixx="0.005902770308334927" iyy="0.006875440791084524" izz="0.0064890490351207746" ixy="1.7229241515976818e-06" iyz="-1.1841492390707912e-06" ixz="0.001799430879032202" />
        </inertial>
        <visual name="TEKO_BoardSupport-1_visual">
            <origin xyz="-0.17250000000000001 -0.067 0.0575" rpy="0.0 -0.0 0.0" />
            <geometry>
                <mesh filename="meshes/TEKO_BoardSupport-1.stl" scale="0.001 0.001 0.001" />
            </geometry>
        </visual>
        <collision name="TEKO_BoardSupport-1_collision">
            <origin xyz="-0.17250000000000001 -0.067 0.0575" rpy="0.0 -0.0 0.0" />
            <geometry>
                <mesh filename="meshes/TEKO_BoardSupport-1.stl" scale="0.001 0.001 0.001" />
            </geometry>
        </collision>
    </link>
    <link name="TEKO_LidarBase">
        <inertial>
            <origin xyz="0.0021448525559021815 -0.04764835145088284 0.047600137581236955" rpy="0.0 -0.0 0.0" />
            <mass value="1.1102585236884506" />
            <inertia ixx="0.0018941551034162944" iyy="0.0010640636716937359" izz="0.0011125938431862867" ixy="6.285840197465219e-05" iyz="-3.458786969206716e-07" ixz="1.1007300877713386e-06" />
        </inertial>
        <visual name="TEKO_LidarBase_visual">
            <origin xyz="-0.057950002458691585 -0.17250000000000004 0.0477" rpy="1.5707963267948966 -0.0 1.5707963267948968" />
            <geometry>
                <mesh filename="meshes/TEKO_LidarBase.stl" scale="0.001 0.001 0.001" />
            </geometry>
        </visual>
        <collision name="TEKO_LidarBase_collision">
            <origin xyz="-0.057950002458691585 -0.17250000000000004 0.0477" rpy="1.5707963267948966 -0.0 1.5707963267948968" />
            <geometry>
                <mesh filename="meshes/TEKO_LidarBase.stl" scale="0.001 0.001 0.001" />
            </geometry>
        </collision>
    </link>
    <link name="TEKO_Lidar">
        <inertial>
            <origin xyz="1.2434497875801754e-16 -3.776197935464734e-16 0.012793512628552786" rpy="0.0 -0.0 0.0" />
            <mass value="0.7568849745795749" />
            <inertia ixx="0.0002679588604133741" iyy="0.0002679522742183339" izz="0.00045187002761743617" ixy="-4.194475877739061e-18" iyz="1.3594097803562937e-18" ixz="-2.168404344971009e-18" />
        </inertial>
        <visual name="TEKO_Lidar_visual">
            <origin xyz="-0.14500000000000005 -7.105427357601001e-17 0.043267542458691584" rpy="3.141592653589793 -0.0 0.0" />
            <geometry>
                <mesh filename="meshes/TEKO_Lidar.stl" scale="0.001 0.001 0.001" />
            </geometry>
        </visual>
        <collision name="TEKO_Lidar_collision">
            <origin xyz="-0.14500000000000005 -7.105427357601001e-17 0.043267542458691584" rpy="3.141592653589793 -0.0 0.0" />
            <geometry>
                <mesh filename="meshes/TEKO_Lidar.stl" scale="0.001 0.001 0.001" />
            </geometry>
        </collision>
    </link>
    <joint name="TEKO_LidarBase_JointLidar" type="continuous">
        <origin xyz="-0.01418246 -0.0275 0.0477" rpy="-1.5707963267948966 -0.0 1.5707963267948966" />
        <parent link="TEKO_LidarBase" />
        <child link="TEKO_Lidar" />
        <axis xyz="0.0 -0.0 1.0" />
    </joint>
    <joint name="TEKO_Body_FrontRight" type="continuous">
        <origin xyz="0.07426507000000002 0.022212729999999993 0.09565" rpy="-1.5707963267948966 -0.0 0.0" />
        <parent link="TEKO_Body" />
        <child link="TEKO_WheelFrontRight" />
        <axis xyz="0.0 0.0 1.0" />
    </joint>
    <joint name="TEKO_Body_BackRight" type="continuous">
        <origin xyz="-0.09963493 0.022212729999999993 0.09565" rpy="-1.5707963267948966 -0.0 0.0" />
        <parent link="TEKO_Body" />
        <child link="TEKO_WheelBackRight" />
        <axis xyz="0.0 0.0 1.0" />
    </joint>
    <joint name="TEKO_Body_BackLeft" type="continuous">
        <origin xyz="-0.09963493 -0.14178727 0.09565" rpy="1.5707963267948966 -0.0 0.0" />
        <parent link="TEKO_Body" />
        <child link="TEKO_WheelBackLeft" />
        <axis xyz="0.0 0.0 1.0" />
    </joint>
    <joint name="TEKO_Body_FrontLeft" type="continuous">
        <origin xyz="0.07426507000000002 -0.14178727 0.09565" rpy="1.5707963267948966 -0.0 0.0" />
        <parent link="TEKO_Body" />
        <child link="TEKO_WheelFrontLeft" />
        <axis xyz="0.0 0.0 1.0" />
    </joint>
    <joint name="TEKO_Body_JointMotorLeft" type="fixed">
        <origin xyz="-0.09963493 -0.13178727 0.09565" rpy="-1.5707963267948966 -0.0 0.0" />
        <parent link="TEKO_Body" />
        <child link="TEKO_MotorRight-1" />
    </joint>
    <joint name="TEKO_Body_JointMotorRight" type="fixed">
        <origin xyz="-0.09963493 0.012212730000000002 0.09565" rpy="1.5707963267948966 -0.0 0.0" />
        <parent link="TEKO_Body" />
        <child link="TEKO_MotorRight" />
    </joint>
    <joint name="TEKO_ChassiUpper_JointGlassUnder" type="fixed">
        <origin xyz="-0.17250000000000001 0.067 -0.07730000000000001" rpy="0.0 -0.0 0.0" />
        <parent link="TEKO_ChassiUpper" />
        <child link="TEKO_GlassBase" />
    </joint>
    <joint name="TEKO_ChassiUpper_JointBothChassis" type="fixed">
        <origin xyz="0.00630165 -0.05955872 -0.0575" rpy="3.141592653589793 -0.0 0.0" />
        <parent link="TEKO_ChassiUpper" />
        <child link="TEKO_Body" />
    </joint>
    <joint name="TEKO_ChassiUpper_JointConnectorRear" type="fixed">
        <origin xyz="-0.17250000000000001 0.0 -0.057999999999999996" rpy="1.5707963267948966 9.310046328093557e-17 -1.5707963267948977" />
        <parent link="TEKO_ChassiUpper" />
        <child link="TEKO_ConnectorRear" />
    </joint>
    <joint name="TEKO_WallBack_JointCamera" type="fixed">
        <origin xyz="-0.003000000000000007 0.0 0.11499528" rpy="1.5707963267948966 -0.0 -1.570796326794897" />
        <parent link="TEKO_WallBack" />
        <child link="TEKO_Camera" />
    </joint>
    <joint name="TEKO_ChassiUpper_JointBackWall" type="fixed">
        <origin xyz="-0.168625 0.0 -0.0575" rpy="0.0 -0.0 0.0" />
        <parent link="TEKO_ChassiUpper" />
        <child link="TEKO_WallBack" />
    </joint>
    <joint name="TEKO_ChassiUpper_JointArucoSupport" type="fixed">
        <origin xyz="0.17250000000000001 0.067 -0.0575" rpy="0.0 -0.0 0.0" />
        <parent link="TEKO_ChassiUpper" />
        <child link="TEKO_BoardSupport-1" />
    </joint>
    <joint name="TEKO_ChassiUpper_JointLidarSupport" type="fixed">
        <origin xyz="0.17250000000000001 -0.0477 0.057999999999999996" rpy="-1.5707963267948966 -1.5707963267948966 0" />
        <parent link="TEKO_ChassiUpper" />
        <child link="TEKO_LidarBase" />
    </joint>
    <joint name="TEKO_ChassiUpper_JointRoof" type="fixed">
        <origin xyz="0.17250000000000001 0.067 0.07730000000000001" rpy="0.0 -0.0 0.0" />
        <parent link="TEKO_ChassiUpper" />
        <child link="TEKO_Roof" />
    </joint>
    <joint name="TEKO_ChassiUpper_JointBoards" type="fixed">
        <origin xyz="0.0327 0.0668 -0.0575" rpy="-1.5707963267948966 -1.3559975873284387e-14 1.570796326794902" />
        <parent link="TEKO_ChassiUpper" />
        <child link="TEKO_BoardSupport" />
    </joint>
    <joint name="TEKO_ChassiUpper_JointConnectorFront" type="fixed">
        <origin xyz="0.17250000000000001 0.0 -0.06475" rpy="-1.5707963267948966 -9.007894723125006e-17 -1.5707963267948966" />
        <parent link="TEKO_ChassiUpper" />
        <child link="TEKO_ConnectorFront" />
    </joint>
    <joint name="TEKO_BoardSupport-1_JointArucoGlass" type="fixed">
        <origin xyz="-0.021999999999999992 -0.019000000000000003 0.00699999" rpy="0.0 -0.0 0.0" />
        <parent link="TEKO_BoardSupport-1" />
        <child link="TEKO_GlassAruco" />
    </joint>
</robot>